<?xml version="1.0" encoding="UTF-8"?>
<!-- Generated by org.testng.reporters.JUnitReportReporter -->
<testsuite hostname="xlh-028" name="test.apptest.chuangye.AppChuangyeEnterIncubator" tests="1" failures="0" timestamp="22 Dec 2016 05:16:14 GMT" time="105.180" errors="1">
  <testcase name="chuangyeEnterIncubator" time="105.180" classname="test.apptest.chuangye.AppChuangyeEnterIncubator">
    <error type="java.lang.AssertionError" message="入驻失败！ expected [true] but found [false]">
      <![CDATA[java.lang.AssertionError: 入驻失败！ expected [true] but found [false]
	at org.testng.Assert.fail(Assert.java:94)
	at org.testng.Assert.failNotEquals(Assert.java:494)
	at org.testng.Assert.assertTrue(Assert.java:42)
	at test.apptest.chuangye.AppChuangyeEnterIncubator.chuangyeEnterIncubator(AppChuangyeEnterIncubator.java:109)
	at sun.reflect.NativeMethodAccessorImpl.invoke0(Native Method)
	at sun.reflect.NativeMethodAccessorImpl.invoke(Unknown Source)
	at sun.reflect.DelegatingMethodAccessorImpl.invoke(Unknown Source)
	at java.lang.reflect.Method.invoke(Unknown Source)
	at org.testng.internal.MethodInvocationHelper.invokeMethod(MethodInvocationHelper.java:84)
	at org.testng.internal.InvokeMethodRunnable.runOne(InvokeMethodRunnable.java:46)
	at org.testng.internal.InvokeMethodRunnable.run(InvokeMethodRunnable.java:37)
	at java.util.concurrent.Executors$RunnableAdapter.call(Unknown Source)
	at java.util.concurrent.FutureTask$Sync.innerRun(Unknown Source)
	at java.util.concurrent.FutureTask.run(Unknown Source)
	at java.util.concurrent.ThreadPoolExecutor$Worker.runTask(Unknown Source)
	at java.util.concurrent.ThreadPoolExecutor$Worker.run(Unknown Source)
	at java.lang.Thread.run(Unknown Source)
]]>
    </error>
  </testcase> <!-- chuangyeEnterIncubator -->
</testsuite> <!-- test.apptest.chuangye.AppChuangyeEnterIncubator -->
